Workbook

Sheet 1. Instructions
B1: AI RISK ASSESSMENT FRAMEWORK
B4: Inspired by NIST AI RMF | ISO/IEC 42001 | Enterprise GRC Best Practices
B6: ABOUT THIS TOOLKIT
B7: This toolkit provides a structured, repeatable methodology for assessing AI system risk across six critical domains.
B8: It is aligned with the NIST AI Risk Management Framework (AI RMF 1.0) and ISO/IEC 42001 AI Management Systems standard.
B9: Intended for: GRC professionals, AI governance leads, security teams, compliance officers, and portfolio demonstration.
B11: HOW TO USE THIS WORKBOOK
B12: Step | C12: Action | D12: Details
B13: Step 1 | C13: Open Sheet 2 – Risk Assessment Checklist | D13: Answer each question for your target AI system. Score 1–5 per question.
B14: Step 2 | C14: Review Scoring Logic | D14: Each domain has a weight. Weighted scores roll up automatically.
B15: Step 3 | C15: View Sheet 3 – Scoring Dashboard | D15: Dashboard auto-calculates domain scores, overall risk rating, and heat map.
B16: Step 4 | C16: Review Sheet 4 – Risk Summary | D16: Review top risks, recommendations, and final assessment output.
B18: SCORING SCALE REFERENCE
B19: Score | C19: Meaning | D19: Control Maturity
B20: 1 – Very Low | C20: Risk is negligible or fully mitigated | D20: Strong, documented, tested controls in place
B21: 2 – Low | C21: Risk is minor with adequate controls | D21: Controls exist and are mostly effective
B22: 3 – Moderate | C22: Risk is present with partial controls | D22: Controls exist but gaps remain
B23: 4 – High | C23: Significant risk with weak/missing controls | D23: Controls are minimal or ad hoc
B24: 5 – Critical | C24: Severe risk with no meaningful controls | D24: No controls or controls are ineffective
B26: DOMAIN WEIGHTS & RISK THRESHOLDS
B27: Domain | C27: Weight | D27: Rationale
B28: Security Risks | C28: 25% | D28: Highest impact — adversarial attacks, data leakage, prompt injection
B29: Data Privacy & Protection | C29: 20% | D29: Regulatory exposure (GDPR, CCPA) and reputational damage
B30: Bias & Fairness | C30: 15% | D30: Legal liability and ethical accountability
B31: Compliance & Legal Risk | C31: 15% | D31: Regulatory penalties and audit findings
B32: Accountability & Governance | C32: 15% | D32: Oversight gaps multiply all other risks
B33: Model Transparency & Explainability | C33: 10% | D33: Operational risk; lower direct impact but enables oversight
B36: AI Risk Assessment Framework v1.0 | Confidential | For portfolio/professional use

Sheet 2. Risk Assessment Checklist
B1: AI RISK ASSESSMENT — QUESTION CHECKLIST
B2: Instructions: Score each question 1 (Very Low) to 5 (Critical). Add assessor notes in the Notes column.
B3: # | C3: Assessment Question | D3: Risk Level | E3: Score (1–5) | F3: Weight | G3: Notes / Evidence
B4: D1 — BIAS & FAIRNESS
B5: D1.1 | C5: Has the training data been audited for demographic or historical bias? | D5: High | E5: 3 | F5: 0.15
B6: D1.2 | C6: Are fairness metrics (e.g., equalized odds, demographic parity) defined and monitored? | D6: High | E6: 3 | F6: 0.15
B7: D1.3 | C7: Does the system undergo bias testing across different demographic groups? | D7: High | E7: 3 | F7: 0.15
B8: D1.4 | C8: Are disparate impact analyses conducted before deployment in high-stakes decisions? | D8: High | E8: 3 | F8: 0.15
B9: D1.5 | C9: Is there a documented process to remediate bias when discovered post-deployment? | D9: Medium | E9: 3 | F9: 0.15
B10: D1.6 | C10: Are proxy variables that could introduce indirect bias identified and controlled? | D10: Medium | E10: 3 | F10: 0.15
B11: D1.7 | C11: Is model performance (accuracy, FPR, FNR) monitored separately per subgroup? | D11: Medium | E11: 3 | F11: 0.15
B13: D2 — DATA PRIVACY & PROTECTION
B14: D2.1 | C14: Is PII/sensitive data identified, classified, and minimized in training datasets? | D14: High | E14: 3 | F14: 0.2
B15: D2.2 | C15: Are data retention policies enforced, with deletion schedules documented? | D15: High | E15: 3 | F15: 0.2
B16: D2.3 | C16: Is consent obtained and recorded for personal data used in model training? | D16: High | E16: 3 | F16: 0.2
B17: D2.4 | C17: Is differential privacy or data anonymization applied to training datasets? | D17: High | E17: 3 | F17: 0.2
B18: D2.5 | C18: Are data processing activities documented in compliance with GDPR/CCPA requirements? | D18: High | E18: 3 | F18: 0.2
B19: D2.6 | C19: Is there a process to honor data subject access requests (DSAR) relating to AI outputs? | D19: Medium | E19: 3 | F19: 0.2
B20: D2.7 | C20: Is data shared with third-party vendors governed by DPAs and contractual controls? | D20: Medium | E20: 3 | F20: 0.2
B21: D2.8 | C21: Are model memorization and training data extraction risks evaluated? | D21: High | E21: 3 | F21: 0.2
B23: D3 — MODEL TRANSPARENCY & EXPLAINABILITY
B24: D3.1 | C24: Can the system provide human-understandable explanations for its outputs? | D24: Medium | E24: 3 | F24: 0.1
B25: D3.2 | C25: Is model documentation (model cards, datasheets) maintained and publicly available? | D25: Medium | E25: 3 | F25: 0.1
B26: D3.3 | C26: Are feature importance and decision attribution methods implemented? | D26: Medium | E26: 3 | F26: 0.1
B27: D3.4 | C27: Are stakeholders (including end-users) informed that they are interacting with AI? | D27: High | E27: 3 | F27: 0.1
B28: D3.5 | C28: Is there a mechanism for users to contest AI-generated decisions? | D28: High | E28: 3 | F28: 0.1
B29: D3.6 | C29: Are model limitations, known failure modes, and confidence levels documented? | D29: Medium | E29: 3 | F29: 0.1
B30: D3.7 | C30: Are audit logs of model inputs and outputs retained for forensic analysis? | D30: Medium | E30: 3 | F30: 0.1
B32: D4 — SECURITY RISKS
B33: D4.1 | C33: Has the model been tested against adversarial input attacks (e.g., evasion, poisoning)? | D33: Critical | E33: 3 | F33: 0.25
B34: D4.2 | C34: Are prompt injection and jailbreak attack vectors identified and mitigated? | D34: Critical | E34: 3 | F34: 0.25
B35: D4.3 | C35: Is model inversion or membership inference attack risk assessed and controlled? | D35: High | E35: 3 | F35: 0.25
B36: D4.4 | C36: Are API rate limits, authentication, and access controls enforced for model endpoints? | D36: High | E36: 3 | F36: 0.25
B37: D4.5 | C37: Is the model supply chain (training data, dependencies, libraries) verified for integrity? | D37: High | E37: 3 | F37: 0.25
B38: D4.6 | C38: Are outputs sanitized to prevent data leakage of sensitive training information? | D38: Critical | E38: 3 | F38: 0.25
B39: D4.7 | C39: Is there a documented incident response plan specific to AI system compromise? | D39: High | E39: 3 | F39: 0.25
B40: D4.8 | C40: Are model weights and intellectual property protected against exfiltration? | D40: High | E40: 3 | F40: 0.25
B41: D4.9 | C41: Is continuous monitoring in place to detect anomalous model behavior in production? | D41: High | E41: 3 | F41: 0.25
B43: D5 — ACCOUNTABILITY & GOVERNANCE
B44: D5.1 | C44: Is there a designated AI Risk Owner or AI Ethics Officer with clear accountability? | D44: High | E44: 3 | F44: 0.15
...

Sheet 3. Scoring Dashboard
B1: SCORING DASHBOARD
B2: Scores auto-populate from the Checklist sheet. Update individual question scores on Sheet 2.
B4: Domain | C4: Weight | D4: # Questions | E4: Avg Score (1–5) | F4: Weighted Score | G4: Risk Level
B5: D1 — BIAS & FAIRNESS | C5: 0.15 | D5: 7 | E5: =AVERAGE('2. Risk Assessment Checklist'!E5:E11) -> 3 | F5: =E5*C5 -> 0.45 | G5: =IF(E5>=4.5,"CRITICAL",IF(E5>=3.5,"HIGH",IF(E5>=2.5,"MODERATE","LOW"))) -> MODERATE
B6: D2 — DATA PRIVACY & PROTECTION | C6: 0.2 | D6: 8 | E6: =AVERAGE('2. Risk Assessment Checklist'!E14:E21) -> 3 | F6: =E6*C6 -> 0.6 | G6: =IF(E6>=4.5,"CRITICAL",IF(E6>=3.5,"HIGH",IF(E6>=2.5,"MODERATE","LOW"))) -> MODERATE
B7: D3 — MODEL TRANSPARENCY & EXPLAINABILITY | C7: 0.1 | D7: 7 | E7: =AVERAGE('2. Risk Assessment Checklist'!E24:E30) -> 3 | F7: =E7*C7 -> 0.3 | G7: =IF(E7>=4.5,"CRITICAL",IF(E7>=3.5,"HIGH",IF(E7>=2.5,"MODERATE","LOW"))) -> MODERATE
B8: D4 — SECURITY RISKS | C8: 0.25 | D8: 9 | E8: =AVERAGE('2. Risk Assessment Checklist'!E33:E41) -> 3 | F8: =E8*C8 -> 0.75 | G8: =IF(E8>=4.5,"CRITICAL",IF(E8>=3.5,"HIGH",IF(E8>=2.5,"MODERATE","LOW"))) -> MODERATE
B9: D5 — ACCOUNTABILITY & GOVERNANCE | C9: 0.15 | D9: 8 | E9: =AVERAGE('2. Risk Assessment Checklist'!E44:E51) -> 3 | F9: =E9*C9 -> 0.45 | G9: =IF(E9>=4.5,"CRITICAL",IF(E9>=3.5,"HIGH",IF(E9>=2.5,"MODERATE","LOW"))) -> MODERATE
B10: D6 — COMPLIANCE & LEGAL RISK | C10: 0.15 | D10: 7 | E10: =AVERAGE('2. Risk Assessment Checklist'!E54:E60) -> 3 | F10: =E10*C10 -> 0.45 | G10: =IF(E10>=4.5,"CRITICAL",IF(E10>=3.5,"HIGH",IF(E10>=2.5,"MODERATE","LOW"))) -> MODERATE
B11: OVERALL WEIGHTED RISK SCORE | C11: 100% | D11: =7+8+7+9+8+7 -> 46 | E11: =SUM(F5:F10) -> 3 | F11: =IF(E11>=4.5,"⚠ CRITICAL",IF(E11>=3.5,"🔴 HIGH",IF(E11>=2.5,"🟡 MODERATE","🟢 LOW"))) -> 🟡 MODERATE
B13: RISK RATING THRESHOLDS
B14: LOW | C14: Score < 2.5 | D14: Acceptable risk. Maintain controls and monitor.
B15: MODERATE | C15: 2.5 – 3.4 | D15: Elevated risk. Implement mitigations within 90 days.
B16: HIGH | C16: 3.5 – 4.4 | D16: Significant risk. Immediate remediation plan required.
B17: CRITICAL | C17: Score ≥ 4.5 | D17: Severe risk. Consider halting deployment pending remediation.

Sheet 4. Risk Summary
B1: AI RISK ASSESSMENT REPORT — SAMPLE: ChatGPT (GPT-4)
B2: System Assessed: | C2: ChatGPT (GPT-4, OpenAI)
B3: Assessment Date: | C3: April 2026
B4: Assessor: | C4: AI GRC Portfolio Project
B5: Classification: | C5: CONFIDENTIAL — SAMPLE
B6: Framework: | C6: NIST AI RMF 1.0 | ISO/IEC 42001
B8: DOMAIN RISK SCORES — CHATGPT SAMPLE ASSESSMENT
B9: Domain | C9: Weight | D9: Score (1–5) | E9: Weighted Score | F9: Risk Level
B10: Bias & Fairness | C10: 0.15 | D10: 3.4 | E10: 0.51 | F10: MODERATE
B11: Data Privacy & Protection | C11: 0.2 | D11: 3.8 | E11: 0.76 | F11: HIGH
B12: Model Transparency & Explainability | C12: 0.1 | D12: 3.6 | E12: 0.36 | F12: HIGH
B13: Security Risks | C13: 0.25 | D13: 4.1 | E13: 1.025 | F13: HIGH
B14: Accountability & Governance | C14: 0.15 | D14: 3.2 | E14: 0.48 | F14: MODERATE
B15: Compliance & Legal Risk | C15: 0.15 | D15: 3.5 | E15: 0.525 | F15: HIGH
B16: OVERALL RISK SCORE | C16: 100% | D16: 3.66 | E16: 🔴 HIGH RISK (3.72)
B18: TOP 5 IDENTIFIED RISKS
B19: # | C19: Risk | D19: Domain | E19: Severity | F19: Recommended Mitigation
B20: 1 | C20: Prompt injection enabling policy bypass or data exfiltration | D20: Security | E20: CRITICAL | F20: Implement input sanitization, output filtering, and adversarial red-teaming
B21: 2 | C21: Training data memorization leaking PII in model outputs | D21: Data Privacy | E21: HIGH | F21: Apply differential privacy, output monitoring, and PII detection filters
B22: 3 | C22: Opaque reasoning with no contestation mechanism for high-stakes outputs | D22: Transparency | E22: HIGH | F22: Deploy model cards, confidence scores, and user appeal workflows
B23: 4 | C23: Cross-border data transfer non-compliance under GDPR/EU AI Act | D23: Compliance | E23: HIGH | F23: Legal review of data flows; SCCs or data localization controls
B24: 5 | C24: Demographic bias in content moderation or decision-support outputs | D24: Bias & Fairness | E24: MODERATE | F24: Regular fairness audits, subgroup performance monitoring, bias red-teams
B26: KEY RECOMMENDATIONS
B27: Immediate (0–30 days) | C27: Conduct adversarial red-team exercise targeting prompt injection; patch output filters.
B28: Short-term (30–90 days) | C28: Commission independent bias audit; implement subgroup monitoring dashboards.
B29: Medium-term (90–180 days) | C29: Publish model card; establish AI governance committee and AI risk register.
B30: Long-term (180+ days) | C30: Achieve ISO/IEC 42001 certification; integrate AI risk into enterprise ERM program.
B32: AI Risk Assessment Framework v1.0 | Sample Assessment: ChatGPT (GPT-4) | Not for production use without customization
